<?xml version='1.0'?>

<robot name="mogi_bot" xmlns:xacro="http://www.ros.org/wiki/xacro">

<xacro:include filename="$(find navi_stack_hw)/urdf/materials.xacro" />

<link name="base_footprint"></link>
  
<joint name="base_footprint_joint" type="fixed">
    <origin xyz="0 0 0" rpy="0 0 0" />
    <parent link="base_footprint"/>
    <child link="base_link" />
</joint>

<link name='base_link'>
    <pose>0 0 0.1 0 0 0</pose>

    <inertial>
      <mass value="15.0"/>
      <origin xyz="0.0 0 0" rpy=" 0 0 0"/>
      <inertia
          ixx="0.3125" ixy="0" ixz="0"
          iyy="0.725" iyz="0"
          izz="0.8125"
      />
    </inertial>

    <collision name='collision'>
      <origin xyz="0 0 0" rpy=" 0 0 0"/> 
      <geometry>
        <box size=".7 .4 .3"/>
      </geometry>
    </collision>

    <visual name='base_link_visual'>
      <origin xyz="0 0 0" rpy=" 0 0 0"/>
      <geometry>
        <!-- <box size=".7 .4 .3"/> -->
        <mesh filename = "package://navi_stack_hw/meshes/base.dae" scale="1 1 1"/>
      </geometry>
    </visual>

  </link>

<!-- Wheels -->

<!-- front left -->
  <joint type="continuous" name="front_left_wheel_joint">
    <origin xyz="0.2 0.26 -0.12" rpy="0 0 0"/>
    <child link="front_left_wheel"/>
    <parent link="base_link"/>
    <axis xyz="0 1 0" rpy="0 0 0"/>
    <limit effort="100" velocity="10"/>
    <dynamics damping="1.0" friction="1.0"/>
  </joint>

  <link name='front_left_wheel'>
    <inertial>
      <mass value="2.0"/>
      <origin xyz="0 0 0" rpy="0 1.5707 1.5707"/>
      <inertia
          ixx="0.0066667" ixy="0" ixz="0"
          iyy="0.006667" iyz="0"
          izz="0.01"
      />
    </inertial>

    <collision>
      <origin xyz="0 0 0" rpy="0 1.5707 1.5707"/> 
      <geometry>
        <cylinder radius=".1" length=".08"/>
      </geometry>
    </collision>

    <visual name='front_left_wheel_visual'>
      <origin xyz="0 0 0" rpy="0 1.5707 1.5707"/>
      <geometry>
        <!--<cylinder radius=".1" length=".08"/>--> 
        <mesh filename = "package://navi_stack_hw/meshes/wheel.dae"/> 
      </geometry>
       <!-- <material name="green"/>-->
    </visual>
  </link>

<!-- front right -->
  <joint type="continuous" name="front_right_wheel_joint">
    <origin xyz="0.2 -0.26 -0.12" rpy="0 0 0"/>
    <child link="front_right_wheel"/>
    <parent link="base_link"/>
    <axis xyz="0 1 0" rpy="0 0 0"/>
    <limit effort="100" velocity="10"/>
    <dynamics damping="1.0" friction="1.0"/>
  </joint>

  <link name='front_right_wheel'>
    <inertial>
      <mass value="2.0"/>
      <origin xyz="0 0 0" rpy="0 1.5707 1.5707"/>
      <inertia
          ixx="0.0066667" ixy="0" ixz="0"
          iyy="0.006667" iyz="0"
          izz="0.01"
      />
    </inertial>

    <collision>
      <origin xyz="0 0 0" rpy="0 1.5707 1.5707"/> 
      <geometry>
        <cylinder radius=".1" length=".08"/>
      </geometry>
    </collision>

    <visual name='front_right_wheel_visual'>
      <origin xyz="0 0 0" rpy="0 1.5707 1.5707"/>
      <geometry>
        <!-- <cylinder radius=".1" length=".08"/>--> 
        <mesh filename = "package://navi_stack_hw/meshes/wheel.dae"/> 
      </geometry>
       <!-- <material name="green"/>--> 
    </visual>
  </link>

  <!-- rear left -->
  <joint type="continuous" name="rear_left_wheel_joint">
    <origin xyz="-0.2 0.26 -0.12" rpy="0 0 0"/>
    <child link="rear_left_wheel"/>
    <parent link="base_link"/>
    <axis xyz="0 1 0" rpy="0 0 0"/>
    <limit effort="100" velocity="10"/>
    <dynamics damping="1.0" friction="1.0"/>
  </joint>

  <link name='rear_left_wheel'>
    <inertial>
      <mass value="2.0"/>
      <origin xyz="0 0 0" rpy="0 1.5707 1.5707"/>
      <inertia
          ixx="0.0066667" ixy="0" ixz="0"
          iyy="0.006667" iyz="0"
          izz="0.01"
      />
    </inertial>

    <collision>
      <origin xyz="0 0 0" rpy="0 1.5707 1.5707"/> 
      <geometry>
        <cylinder radius=".1" length=".08"/>
      </geometry>
    </collision>

    <visual name='rear_left_wheel_visual'>
      <origin xyz="0 0 0" rpy="0 1.5707 1.5707"/>
      <geometry>
        <!-- <cylinder radius=".1" length=".08"/> -->
        <mesh filename = "package://navi_stack_hw/meshes/wheel.dae"/> 
      </geometry>
       <!-- <material name="green"/> --> 
    </visual>
  </link>

  <!-- rear right -->
  <joint type="continuous" name="rear_right_wheel_joint">
    <origin xyz="-0.2 -0.26 -0.12" rpy="0 0 0"/>
    <child link="rear_right_wheel"/>
    <parent link="base_link"/>
    <axis xyz="0 1 0" rpy="0 0 0"/>
    <limit effort="100" velocity="10"/>
    <dynamics damping="1.0" friction="1.0"/>
  </joint>

  <link name='rear_right_wheel'>
    <inertial>
      <mass value="2.0"/>
      <origin xyz="0 0 0" rpy="0 1.5707 1.5707"/>
      <inertia
          ixx="0.0066667" ixy="0" ixz="0"
          iyy="0.006667" iyz="0"
          izz="0.01"
      />
    </inertial>

    <collision>
      <origin xyz="0 0 0" rpy="0 1.5707 1.5707"/> 
      <geometry>
        <cylinder radius=".1" length=".08"/>
      </geometry>
    </collision>

    <visual name='rear_right_wheel_visual'>
      <origin xyz="0 0 0" rpy="0 1.5707 1.5707"/>
      <geometry>
        <!-- <cylinder radius=".1" length=".08"/>--> 
        <mesh filename = "package://navi_stack_hw/meshes/wheel.dae"/> 
      </geometry>
       <!-- <material name="green"/>--> 
    </visual>
  </link>



</robot>